Workbook

Sheet 2026 tavasz
C3: 46042 | D3: 46049 | E3: 46056 | F3: 46063 | G3: 46070 | H3: 46077 | I3: 46084 | J3: 46091 | K3: 46098 | L3: 46105 | M3: 46112 | N3: 46119 | O3: 46126 | P3: 46133 | Q3: 46140 | R3: 46147 | S3: 46154 | T3: 46162 | U3: Célérték | V3: Leadandó | W3: % | X3: Eddigi fogyás | Y3: Fogyás rank | Z3: Eddigi fogyás % | AA3: Fogyás % rank
C4: 4. hét | D4: 5. hét | E4: 6 .hét | F4: 7. hét | G4: 8. hét | H4: 9 .hét | I4: 10. hét | J4: 11. hét | K4: 12 .hét | L4: 13. hét | M4: 14. hét | N4: 15 .hét | O4: 16. hét | P4: 17. hét | Q4: 18 .hét | R4: 19. hét | S4: 20. hét | T4: 21. hét
B5: Barcsik Kristóf | C5: 116.1 | D5: 116.1 | E5: 116.1 | F5: 113.4 | G5: 113.6 | H5: 113 | I5: 113.5 | J5: 113.5 | T5: {=XLOOKUP(TRUE, C5:S5<>"", C5:S5, , , -1)} -> 113.5 | U5: 112 | V5: =C5-U5 -> 4.1 | W5: =V5/C5 -> 0.035314384 | X5: =C5-T5 -> 2.6 | Y5: =RANK(X5,$X$5:$X$19,0) -> 7 | Z5: =1-T5/C5 -> 0.022394488 | AA5: =RANK(Z5,$Z$5:$Z$19,0) -> 7
B6: Galgóczy Ádám | C6: 101.5 | D6: 101.7 | E6: 100.9 | F6: 101.1 | G6: 101 | H6: 102 | I6: 101.6 | J6: 102.4 | T6: {=XLOOKUP(TRUE, C6:S6<>"", C6:S6, , , -1)} -> 102.4 | U6: 98 | V6: =C6-U6 -> 3.5 | W6: =V6/C6 -> 0.034482759 | X6: =C6-T6 -> -0.9 | Y6: =RANK(X6,$X$5:$X$19,0) -> 14 | Z6: =1-T6/C6 -> -0.0088669951 | AA6: =RANK(Z6,$Z$5:$Z$19,0) -> 14
B7: Jávor Tamás | C7: 116.3 | D7: 116 | E7: 114 | F7: 114.3 | G7: 112.6 | H7: 113.6 | I7: 112.4 | J7: 112 | T7: {=XLOOKUP(TRUE, C7:S7<>"", C7:S7, , , -1)} -> 112 | U7: 113 | V7: =C7-U7 -> 3.3 | W7: =V7/C7 -> 0.028374893 | X7: =C7-T7 -> 4.3 | Y7: =RANK(X7,$X$5:$X$19,0) -> 4 | Z7: =1-T7/C7 -> 0.036973345 | AA7: =RANK(Z7,$Z$5:$Z$19,0) -> 5
B8: Krekuska Gábor | C8: 87.7 | D8: 88 | E8: 88 | F8: 87.7 | G8: 87.7 | H8: 87.2 | I8: 88 | J8: 87.3 | T8: {=XLOOKUP(TRUE, C8:S8<>"", C8:S8, , , -1)} -> 87.3 | U8: 85 | V8: =C8-U8 -> 2.7 | W8: =V8/C8 -> 0.030786773 | X8: =C8-T8 -> 0.4 | Y8: =RANK(X8,$X$5:$X$19,0) -> 10 | Z8: =1-T8/C8 -> 0.0045610034 | AA8: =RANK(Z8,$Z$5:$Z$19,0) -> 10
B9: Molnár György | C9: 88.3 | D9: 87.2 | E9: 86.1 | F9: 85.6 | G9: 84.7 | H9: 83.8 | I9: 85 | J9: 83.8 | T9: {=XLOOKUP(TRUE, C9:S9<>"", C9:S9, , , -1)} -> 83.8 | U9: 80 | V9: =C9-U9 -> 8.3 | W9: =V9/C9 -> 0.093997735 | X9: =C9-T9 -> 4.5 | Y9: =RANK(X9,$X$5:$X$19,0) -> 3 | Z9: =1-T9/C9 -> 0.050962627 | AA9: =RANK(Z9,$Z$5:$Z$19,0) -> 3
B10: Varga Szabolcs | C10: 105.3 | D10: 104 | E10: 104 | F10: 102.6 | G10: 101.9 | H10: 102.3 | I10: 102.3 | J10: 101.3 | T10: {=XLOOKUP(TRUE, C10:S10<>"", C10:S10, , , -1)} -> 101.3 | U10: 95 | V10: =C10-U10 -> 10.3 | W10: =V10/C10 -> 0.097815764 | X10: =C10-T10 -> 4 | Y10: =RANK(X10,$X$5:$X$19,0) -> 5 | Z10: =1-T10/C10 -> 0.037986705 | AA10: =RANK(Z10,$Z$5:$Z$19,0) -> 4
B11: Vaspál Gergő | C11: 92.3 | D11: 92.2 | E11: 91.8 | F11: 92.9 | G11: 93.3 | H11: 91.9 | I11: 92.5 | J11: 92.5 | T11: {=XLOOKUP(TRUE, C11:S11<>"", C11:S11, , , -1)} -> 92.5 | U11: 89 | V11: =C11-U11 -> 3.3 | W11: =V11/C11 -> 0.035752979 | X11: =C11-T11 -> -0.2 | Y11: =RANK(X11,$X$5:$X$19,0) -> 13 | Z11: =1-T11/C11 -> -0.0021668472 | AA11: =RANK(Z11,$Z$5:$Z$19,0) -> 13
B12: Várnoki Ádám | C12: 108.4 | D12: 107 | E12: 107.4 | F12: 106.5 | G12: 104 | H12: 102.9 | I12: 103 | J12: 101.9 | T12: {=XLOOKUP(TRUE, C12:S12<>"", C12:S12, , , -1)} -> 101.9 | U12: 100 | V12: =C12-U12 -> 8.4 | W12: =V12/C12 -> 0.077490775 | X12: =C12-T12 -> 6.5 | Y12: =RANK(X12,$X$5:$X$19,0) -> 1 | Z12: =1-T12/C12 -> 0.0599631 | AA12: =RANK(Z12,$Z$5:$Z$19,0) -> 1
B13: Szikora István | C13: 102.1 | D13: 102.2 | E13: 102.8 | F13: 101.7 | G13: 101 | H13: 100.3 | I13: 99.9 | J13: 99.4 | T13: {=XLOOKUP(TRUE, C13:S13<>"", C13:S13, , , -1)} -> 99.4 | U13: 95 | V13: =C13-U13 -> 7.1 | W13: =V13/C13 -> 0.069539667 | X13: =C13-T13 -> 2.7 | Y13: =RANK(X13,$X$5:$X$19,0) -> 6 | Z13: =1-T13/C13 -> 0.026444662 | AA13: =RANK(Z13,$Z$5:$Z$19,0) -> 6
B14: Kováts Tibor | C14: 97.2 | D14: 97.7 | E14: 97.7 | F14: 96.9 | G14: 97.5 | H14: 97.5 | I14: 97.6 | J14: 97.2 | T14: {=XLOOKUP(TRUE, C14:S14<>"", C14:S14, , , -1)} -> 97.2 | U14: 95.9 | V14: =C14-U14 -> 1.3 | W14: =V14/C14 -> 0.013374486 | X14: =C14-T14 -> 0 | Y14: =RANK(X14,$X$5:$X$19,0) -> 12 | Z14: =1-T14/C14 -> 0 | AA14: =RANK(Z14,$Z$5:$Z$19,0) -> 12
B15: Zorván Zoárd | C15: 80.1 | D15: 79.9 | E15: 79.5 | F15: 77.3 | G15: 77.7 | H15: 75.7 | I15: 75.2 | J15: 75.4 | T15: {=XLOOKUP(TRUE, C15:S15<>"", C15:S15, , , -1)} -> 75.4 | U15: 72 | V15: =C15-U15 -> 8.1 | W15: =V15/C15 -> 0.1011236 | X15: =C15-T15 -> 4.7 | Y15: =RANK(X15,$X$5:$X$19,0) -> 2 | Z15: =1-T15/C15 -> 0.058676654 | AA15: =RANK(Z15,$Z$5:$Z$19,0) -> 2
B16: Beötthy Tímea | C16: 63.1 | D16: 63.1 | E16: 63.1 | F16: 63.4 | G16: 62.7 | H16: 61.7 | I16: 61.9 | J16: 63 | T16: {=XLOOKUP(TRUE, C16:S16<>"", C16:S16, , , -1)} -> 63 | U16: 55 | V16: =C16-U16 -> 8.1 | W16: =V16/C16 -> 0.12836767 | X16: =C16-T16 -> 0.1 | Y16: =RANK(X16,$X$5:$X$19,0) -> 11 | Z16: =1-T16/C16 -> 0.0015847861 | AA16: =RANK(Z16,$Z$5:$Z$19,0) -> 11
B17: Kellős György | C17: 68.6 | D17: 68.4 | E17: 69.2 | F17: 69.7 | G17: 69.4 | H17: 69.9 | I17: 68.9 | J17: 69.6 | T17: {=XLOOKUP(TRUE, C17:S17<>"", C17:S17, , , -1)} -> 69.6 | U17: 72 | V17: =C17-U17 -> -3.4 | W17: =V17/C17 -> -0.049562682 | X17: =C17-T17 -> -1 | Y17: =RANK(X17,$X$5:$X$19,0) -> 15 | Z17: =1-T17/C17 -> -0.014577259 | AA17: =RANK(Z17,$Z$5:$Z$19,0) -> 15
B18: Jákob Tamás | C18: 103 | D18: 103 | E18: 103 | F18: 103 | G18: 103 | H18: 103 | I18: 103 | J18: 102.2 | T18: {=XLOOKUP(TRUE, C18:S18<>"", C18:S18, , , -1)} -> 102.2 | U18: 97 | V18: =I18-U18 -> 6 | W18: =V18/I18 -> 0.058252427 | X18: =C18-T18 -> 0.8 | Y18: =RANK(X18,$X$5:$X$19,0) -> 9 | Z18: =1-T18/C18 -> 0.0077669903 | AA18: =RANK(Z18,$Z$5:$Z$19,0) -> 9
B19: Tóth Roland | C19: 93.6 | D19: 93.6 | E19: 93.6 | F19: 93.6 | G19: 93.6 | H19: 93.6 | I19: 93.6 | J19: 92.4 | T19: {=XLOOKUP(TRUE, C19:S19<>"", C19:S19, , , -1)} -> 92.4 | U19: 83.6 | V19: =I19-U19 -> 10 | W19: =V19/I19 -> 0.10683761 | X19: =C19-T19 -> 1.2 | Y19: =RANK(X19,$X$5:$X$19,0) -> 8 | Z19: =1-T19/C19 -> 0.012820513 | AA19: =RANK(Z19,$Z$5:$Z$19,0) -> 8
B23: Szabó Zoltán | I23: 66.5 | J23: 63.8

Sheet 2026 Tavasz diagram
C4: ='2026 tavasz'!C4 -> 4. hét | D4: ='2026 tavasz'!D4 -> 5. hét | E4: ='2026 tavasz'!E4 -> 6 .hét | F4: ='2026 tavasz'!F4 -> 7. hét | G4: ='2026 tavasz'!G4 -> 8. hét | H4: ='2026 tavasz'!H4 -> 9 .hét | I4: ='2026 tavasz'!I4 -> 10. hét | J4: ='2026 tavasz'!J4 -> 11. hét | ... Q4: ='2026 tavasz'!Q4 -> 18 .hét | R4: ='2026 tavasz'!U4 | S4: Fogyás
B5: ='2026 tavasz'!B5 -> Barcsik Kristóf | C5: ='2026 tavasz'!C5 -> 116.1 | D5: ='2026 tavasz'!D5 -> 116.1 | E5: ='2026 tavasz'!E5 -> 116.1 | F5: ='2026 tavasz'!F5 -> 113.4 | G5: ='2026 tavasz'!G5 -> 113.6 | H5: ='2026 tavasz'!H5 -> 113 | I5: ='2026 tavasz'!I5 -> 113.5 | ... R5: ='2026 tavasz'!R5 | S5: =C5-R5 -> 116.1
B6: ='2026 tavasz'!B6 -> Galgóczy Ádám | C6: ='2026 tavasz'!C6 -> 101.5 | D6: ='2026 tavasz'!D6 -> 101.7 | E6: ='2026 tavasz'!E6 -> 100.9 | F6: ='2026 tavasz'!F6 -> 101.1 | G6: ='2026 tavasz'!G6 -> 101 | H6: ='2026 tavasz'!H6 -> 102 | I6: ='2026 tavasz'!I6 -> 101.6 | ... R6: ='2026 tavasz'!R6 | S6: =C6-R6 -> 101.5
B7: ='2026 tavasz'!B7 -> Jávor Tamás | C7: ='2026 tavasz'!C7 -> 116.3 | D7: ='2026 tavasz'!D7 -> 116 | E7: ='2026 tavasz'!E7 -> 114 | F7: ='2026 tavasz'!F7 -> 114.3 | G7: ='2026 tavasz'!G7 -> 112.6 | H7: ='2026 tavasz'!H7 -> 113.6 | I7: ='2026 tavasz'!I7 -> 112.4 | ... R7: ='2026 tavasz'!R7 | S7: =C7-R7 -> 116.3
B8: ='2026 tavasz'!B8 -> Krekuska Gábor | C8: ='2026 tavasz'!C8 -> 87.7 | D8: ='2026 tavasz'!D8 -> 88 | E8: ='2026 tavasz'!E8 -> 88 | F8: ='2026 tavasz'!F8 -> 87.7 | G8: ='2026 tavasz'!G8 -> 87.7 | H8: ='2026 tavasz'!H8 -> 87.2 | I8: ='2026 tavasz'!I8 -> 88 | ... R8: ='2026 tavasz'!R8 | S8: =C8-R8 -> 87.7
B9: ='2026 tavasz'!B9 -> Molnár György | C9: ='2026 tavasz'!C9 -> 88.3 | D9: ='2026 tavasz'!D9 -> 87.2 | E9: ='2026 tavasz'!E9 -> 86.1 | F9: ='2026 tavasz'!F9 -> 85.6 | G9: ='2026 tavasz'!G9 -> 84.7 | H9: ='2026 tavasz'!H9 -> 83.8 | I9: ='2026 tavasz'!I9 -> 85 | ... R9: ='2026 tavasz'!R9 | S9: =C9-R9 -> 88.3
B10: ='2026 tavasz'!B10 -> Varga Szabolcs | C10: ='2026 tavasz'!C10 -> 105.3 | D10: ='2026 tavasz'!D10 -> 104 | E10: ='2026 tavasz'!E10 -> 104 | F10: ='2026 tavasz'!F10 -> 102.6 | G10: ='2026 tavasz'!G10 -> 101.9 | H10: ='2026 tavasz'!H10 -> 102.3 | I10: ='2026 tavasz'!I10 -> 102.3 | ... R10: ='2026 tavasz'!R10 | S10: =C10-R10 -> 105.3
B11: ='2026 tavasz'!B11 -> Vaspál Gergő | C11: ='2026 tavasz'!C11 -> 92.3 | D11: ='2026 tavasz'!D11 -> 92.2 | E11: ='2026 tavasz'!E11 -> 91.8 | F11: ='2026 tavasz'!F11 -> 92.9 | G11: ='2026 tavasz'!G11 -> 93.3 | H11: ='2026 tavasz'!H11 -> 91.9 | I11: ='2026 tavasz'!I11 -> 92.5 | ... R11: ='2026 tavasz'!R11 | S11: =C11-R11 -> 92.3
B12: ='2026 tavasz'!B12 -> Várnoki Ádám | C12: ='2026 tavasz'!C12 -> 108.4 | D12: ='2026 tavasz'!D12 -> 107 | E12: ='2026 tavasz'!E12 -> 107.4 | F12: ='2026 tavasz'!F12 -> 106.5 | G12: ='2026 tavasz'!G12 -> 104 | H12: ='2026 tavasz'!H12 -> 102.9 | I12: ='2026 tavasz'!I12 -> 103 | ... R12: ='2026 tavasz'!R12 | S12: =C12-R12 -> 108.4
B13: ='2026 tavasz'!B13 -> Szikora István | C13: ='2026 tavasz'!C13 -> 102.1 | D13: ='2026 tavasz'!D13 -> 102.2 | E13: ='2026 tavasz'!E13 -> 102.8 | F13: ='2026 tavasz'!F13 -> 101.7 | G13: ='2026 tavasz'!G13 -> 101 | H13: ='2026 tavasz'!H13 -> 100.3 | I13: ='2026 tavasz'!I13 -> 99.9 | ... R13: ='2026 tavasz'!R13 | S13: =C13-R13 -> 102.1
B14: ='2026 tavasz'!B14 -> Kováts Tibor | C14: ='2026 tavasz'!C14 -> 97.2 | D14: ='2026 tavasz'!D14 -> 97.7 | E14: ='2026 tavasz'!E14 -> 97.7 | F14: ='2026 tavasz'!F14 -> 96.9 | G14: ='2026 tavasz'!G14 -> 97.5 | H14: ='2026 tavasz'!H14 -> 97.5 | I14: ='2026 tavasz'!I14 -> 97.6 | ... Q14: ='2026 tavasz'!Q14 | S14: =C14-R14 -> 97.2
B15: ='2026 tavasz'!B15 -> Zorván Zoárd | C15: ='2026 tavasz'!C15 -> 80.1 | D15: ='2026 tavasz'!D15 -> 79.9 | E15: ='2026 tavasz'!E15 -> 79.5 | F15: ='2026 tavasz'!F15 -> 77.3 | G15: ='2026 tavasz'!G15 -> 77.7 | H15: ='2026 tavasz'!H15 -> 75.7 | I15: ='2026 tavasz'!I15 -> 75.2 | ... Q15: ='2026 tavasz'!Q15 | S15: =C15-R15 -> 80.1
B16: ='2026 tavasz'!B16 -> Beötthy Tímea | C16: ='2026 tavasz'!C16 -> 63.1 | D16: ='2026 tavasz'!D16 -> 63.1 | E16: ='2026 tavasz'!E16 -> 63.1 | F16: ='2026 tavasz'!F16 -> 63.4 | G16: ='2026 tavasz'!G16 -> 62.7 | H16: ='2026 tavasz'!H16 -> 61.7 | I16: ='2026 tavasz'!I16 -> 61.9 | ... Q16: ='2026 tavasz'!Q16 | S16: =C16-R16 -> 63.1
B17: ='2026 tavasz'!B17 -> Kellős György | C17: ='2026 tavasz'!C17 -> 68.6 | D17: ='2026 tavasz'!D17 -> 68.4 | E17: ='2026 tavasz'!E17 -> 69.2 | F17: ='2026 tavasz'!F17 -> 69.7 | G17: ='2026 tavasz'!G17 -> 69.4 | H17: ='2026 tavasz'!H17 -> 69.9 | I17: ='2026 tavasz'!I17 -> 68.9 | ... Q17: ='2026 tavasz'!Q17 | S17: =C17-R17 -> 68.6
B18: ='2026 tavasz'!B18 -> Jákob Tamás | C18: ='2026 tavasz'!C18 -> 103 | D18: ='2026 tavasz'!D18 -> 103 | E18: ='2026 tavasz'!E18 -> 103 | F18: ='2026 tavasz'!F18 -> 103 | G18: ='2026 tavasz'!G18 -> 103 | H18: ='2026 tavasz'!H18 -> 103 | I18: ='2026 tavasz'!I18 -> 103 | J18: ='2026 tavasz'!J18 -> 102.2
B19: ='2026 tavasz'!B19 -> Tóth Roland | C19: ='2026 tavasz'!C19 -> 93.6 | D19: ='2026 tavasz'!D19 -> 93.6 | E19: ='2026 tavasz'!E19 -> 93.6 | F19: ='2026 tavasz'!F19 -> 93.6 | G19: ='2026 tavasz'!G19 -> 93.6 | H19: ='2026 tavasz'!H19 -> 93.6 | I19: ='2026 tavasz'!I19 -> 93.6 | J19: ='2026 tavasz'!J19 -> 92.4
C21: =C4 -> 4. hét | D21: =D4 -> 5. hét | E21: =E4 -> 6 .hét | F21: =F4 -> 7. hét | G21: =G4 -> 8. hét | H21: =H4 -> 9 .hét | I21: =I4 -> 10. hét | J21: =J4 -> 11. hét | ... R21: =R4
B22: Barcsik Kristóf | C22: 0 | D22: =IF(D5="","",(D5-$C5)/$C5) -> 0 | E22: =IF(E5="","",(E5-$C5)/$C5) -> 0 | F22: =IF(F5="","",(F5-$C5)/$C5) -> -0.023255814 | G22: =IF(G5="","",(G5-$C5)/$C5) -> -0.021533161 | H22: =IF(H5="","",(H5-$C5)/$C5) -> -0.02670112 | I22: =IF(I5="","",(I5-$C5)/$C5) -> -0.022394488 | J22: =IF(J5="","",(J5-$C5)/$C5) -> -0.022394488 | K22: =IF(K5="","",(K5-$C5)/$C5) | ... R22: =IF(R5="","",(R5-$C5)/$C5)
B23: Galgóczy Ádám | C23: 0 | D23: =IF(D6="","",(D6-$C6)/$C6) -> 0.0019704434 | E23: =IF(E6="","",(E6-$C6)/$C6) -> -0.00591133 | F23: =IF(F6="","",(F6-$C6)/$C6) -> -0.0039408867 | G23: =IF(G6="","",(G6-$C6)/$C6) -> -0.0049261084 | H23: =IF(H6="","",(H6-$C6)/$C6) -> 0.0049261084 | I23: =IF(I6="","",(I6-$C6)/$C6) -> 0.00098522167 | J23: =IF(J6="","",(J6-$C6)/$C6) -> 0.0088669951 | K23: =IF(K6="","",(K6-$C6)/$C6) | ... R23: =IF(R6="","",(R6-$C6)/$C6)
B24: Jávor Tamás | C24: 0 | D24: =IF(D7="","",(D7-$C7)/$C7) -> -0.0025795357 | E24: =IF(E7="","",(E7-$C7)/$C7) -> -0.01977644 | F24: =IF(F7="","",(F7-$C7)/$C7) -> -0.017196905 | G24: =IF(G7="","",(G7-$C7)/$C7) -> -0.031814273 | H24: =IF(H7="","",(H7-$C7)/$C7) -> -0.023215821 | I24: =IF(I7="","",(I7-$C7)/$C7) -> -0.033533964 | J24: =IF(J7="","",(J7-$C7)/$C7) -> -0.036973345 | K24: =IF(K7="","",(K7-$C7)/$C7) | ... R24: =IF(R7="","",(R7-$C7)/$C7)
B25: Krekuska Gábor | C25: 0 | D25: =IF(D8="","",(D8-$C8)/$C8) -> 0.0034207526 | E25: =IF(E8="","",(E8-$C8)/$C8) -> 0.0034207526 | F25: =IF(F8="","",(F8-$C8)/$C8) -> 0 | G25: =IF(G8="","",(G8-$C8)/$C8) -> 0 | H25: =IF(H8="","",(H8-$C8)/$C8) -> -0.0057012543 | I25: =IF(I8="","",(I8-$C8)/$C8) -> 0.0034207526 | J25: =IF(J8="","",(J8-$C8)/$C8) -> -0.0045610034 | K25: =IF(K8="","",(K8-$C8)/$C8) | ... R25: =IF(R8="","",(R8-$C8)/$C8)
B26: Molnár György | C26: 0 | D26: =IF(D9="","",(D9-$C9)/$C9) -> -0.012457531 | E26: =IF(E9="","",(E9-$C9)/$C9) -> -0.024915062 | F26: =IF(F9="","",(F9-$C9)/$C9) -> -0.030577576 | G26: =IF(G9="","",(G9-$C9)/$C9) -> -0.040770102 | H26: =IF(H9="","",(H9-$C9)/$C9) -> -0.050962627 | I26: =IF(I9="","",(I9-$C9)/$C9) -> -0.037372593 | J26: =IF(J9="","",(J9-$C9)/$C9) -> -0.050962627 | K26: =IF(K9="","",(K9-$C9)/$C9) | ... R26: =IF(R9="","",(R9-$C9)/$C9)
B27: Varga Szabolcs | C27: 0 | D27: =IF(D10="","",(D10-$C10)/$C10) -> -0.012345679 | E27: =IF(E10="","",(E10-$C10)/$C10) -> -0.012345679 | F27: =IF(F10="","",(F10-$C10)/$C10) -> -0.025641026 | G27: =IF(G10="","",(G10-$C10)/$C10) -> -0.032288699 | H27: =IF(H10="","",(H10-$C10)/$C10) -> -0.028490028 | I27: =IF(I10="","",(I10-$C10)/$C10) -> -0.028490028 | J27: =IF(J10="","",(J10-$C10)/$C10) -> -0.037986705 | K27: =IF(K10="","",(K10-$C10)/$C10) | ... R27: =IF(R10="","",(R10-$C10)/$C10)
B28: Vaspál Gergő | C28: 0 | D28: =IF(D11="","",(D11-$C11)/$C11) -> -0.0010834236 | E28: =IF(E11="","",(E11-$C11)/$C11) -> -0.0054171181 | F28: =IF(F11="","",(F11-$C11)/$C11) -> 0.0065005417 | G28: =IF(G11="","",(G11-$C11)/$C11) -> 0.010834236 | H28: =IF(H11="","",(H11-$C11)/$C11) -> -0.0043336945 | I28: =IF(I11="","",(I11-$C11)/$C11) -> 0.0021668472 | J28: =IF(J11="","",(J11-$C11)/$C11) -> 0.0021668472 | K28: =IF(K11="","",(K11-$C11)/$C11) | ... R28: =IF(R11="","",(R11-$C11)/$C11)
B29: Várnoki Ádám | C29: 0 | D29: =IF(D12="","",(D12-$C12)/$C12) -> -0.012915129 | E29: =IF(E12="","",(E12-$C12)/$C12) -> -0.0092250923 | F29: =IF(F12="","",(F12-$C12)/$C12) -> -0.017527675 | G29: =IF(G12="","",(G12-$C12)/$C12) -> -0.040590406 | H29: =IF(H12="","",(H12-$C12)/$C12) -> -0.050738007 | I29: =IF(I12="","",(I12-$C12)/$C12) -> -0.049815498 | J29: =IF(J12="","",(J12-$C12)/$C12) -> -0.0599631 | K29: =IF(K12="","",(K12-$C12)/$C12) | ... R29: =IF(R12="","",(R12-$C12)/$C12)
B30: Szikora István | C30: 0 | D30: =IF(D13="","",(D13-$C13)/$C13) -> 0.00097943193 | E30: =IF(E13="","",(E13-$C13)/$C13) -> 0.0068560235 | F30: =IF(F13="","",(F13-$C13)/$C13) -> -0.0039177277 | G30: =IF(G13="","",(G13-$C13)/$C13) -> -0.010773751 | H30: =IF(H13="","",(H13-$C13)/$C13) -> -0.017629775 | I30: =IF(I13="","",(I13-$C13)/$C13) -> -0.021547502 | J30: =IF(J13="","",(J13-$C13)/$C13) -> -0.026444662 | K30: =IF(K13="","",(K13-$C13)/$C13) | ... R30: =IF(R13="","",(R13-$C13)/$C13)
B31: Kováts Tibor | C31: 0 | D31: =IF(D14="","",(D14-$C14)/$C14) -> 0.0051440329 | E31: =IF(E14="","",(E14-$C14)/$C14) -> 0.0051440329 | F31: =IF(F14="","",(F14-$C14)/$C14) -> -0.0030864198 | G31: =IF(G14="","",(G14-$C14)/$C14) -> 0.0030864198 | H31: =IF(H14="","",(H14-$C14)/$C14) -> 0.0030864198 | I31: =IF(I14="","",(I14-$C14)/$C14) -> 0.0041152263 | J31: =IF(J14="","",(J14-$C14)/$C14) -> 0 | K31: =IF(K14="","",(K14-$C14)/$C14) | ... R31: =IF(R14="","",(R14-$C14)/$C14)
B32: Zorván Zoárd | C32: 0 | D32: =IF(D15="","",(D15-$C15)/$C15) -> -0.0024968789 | E32: =IF(E15="","",(E15-$C15)/$C15) -> -0.0074906367 | F32: =IF(F15="","",(F15-$C15)/$C15) -> -0.034956305 | G32: =IF(G15="","",(G15-$C15)/$C15) -> -0.029962547 | H32: =IF(H15="","",(H15-$C15)/$C15) -> -0.054931336 | I32: =IF(I15="","",(I15-$C15)/$C15) -> -0.061173533 | J32: =IF(J15="","",(J15-$C15)/$C15) -> -0.058676654 | K32: =IF(K15="","",(K15-$C15)/$C15) | ... R32: =IF(R15="","",(R15-$C15)/$C15)
B33: Beötthy Tímea | C33: 0 | D33: =IF(D16="","",(D16-$C16)/$C16) -> 0 | E33: =IF(E16="","",(E16-$C16)/$C16) -> 0 | F33: =IF(F16="","",(F16-$C16)/$C16) -> 0.0047543582 | G33: =IF(G16="","",(G16-$C16)/$C16) -> -0.0063391442 | H33: =IF(H16="","",(H16-$C16)/$C16) -> -0.022187005 | I33: =IF(I16="","",(I16-$C16)/$C16) -> -0.019017433 | J33: =IF(J16="","",(J16-$C16)/$C16) -> -0.0015847861 | K33: =IF(K16="","",(K16-$C16)/$C16) | ... R33: =IF(R16="","",(R16-$C16)/$C16)
B34: Kellős György | C34: 0 | D34: =IF(D17="","",(D17-$C17)/$C17) -> -0.0029154519 | E34: =IF(E17="","",(E17-$C17)/$C17) -> 0.0087463557 | F34: =IF(F17="","",(F17-$C17)/$C17) -> 0.016034985 | G34: =IF(G17="","",(G17-$C17)/$C17) -> 0.011661808 | H34: =IF(H17="","",(H17-$C17)/$C17) -> 0.018950437 | I34: =IF(I17="","",(I17-$C17)/$C17) -> 0.0043731778 | J34: =IF(J17="","",(J17-$C17)/$C17) -> 0.014577259 | K34: =IF(K17="","",(K17-$C17)/$C17) | ... R34: =IF(R17="","",(R17-$C17)/$C17)
B35: Jákob Tamás | C35: 0 | D35: =IF(D18="","",(D18-$C18)/$C18) -> 0 | E35: =IF(E18="","",(E18-$C18)/$C18) -> 0 | F35: =IF(F18="","",(F18-$C18)/$C18) -> 0 | G35: =IF(G18="","",(G18-$C18)/$C18) -> 0 | H35: =IF(H18="","",(H18-$C18)/$C18) -> 0 | I35: =IF(I18="","",(I18-$C18)/$C18) -> 0 | J35: =IF(J18="","",(J18-$C18)/$C18) -> -0.0077669903 | K35: =IF(K18="","",(K18-$C18)/$C18)
B36: Tóth Roland | C36: 0 | D36: =IF(D19="","",(D19-$C19)/$C19) -> 0 | E36: =IF(E19="","",(E19-$C19)/$C19) -> 0 | F36: =IF(F19="","",(F19-$C19)/$C19) -> 0 | G36: =IF(G19="","",(G19-$C19)/$C19) -> 0 | H36: =IF(H19="","",(H19-$C19)/$C19) -> 0 | I36: =IF(I19="","",(I19-$C19)/$C19) -> 0 | J36: =IF(J19="","",(J19-$C19)/$C19) -> -0.012820513 | K36: =IF(K19="","",(K19-$C19)/$C19)
R39: Fogyás [kg] helyezés | S39: Név | T39: Eddigi fogyás
R40: 1 | S40: {=INDEX('2026 tavasz'!$B$5:$Y$19,match(R40, '2026 tavasz'!$Y$5:$Y$19, 0),1)} -> Várnoki Ádám | T40: {=INDEX('2026 tavasz'!$B$5:$Y$19,match(R40, '2026 tavasz'!$Y$5:$Y$19, 0),23)} -> 6.5
R41: 2 | S41: {=INDEX('2026 tavasz'!$B$5:$Y$19,match(R41, '2026 tavasz'!$Y$5:$Y$19, 0),1)} -> Zorván Zoárd | T41: {=INDEX('2026 tavasz'!$B$5:$Y$19,match(R41, '2026 tavasz'!$Y$5:$Y$19, 0),23)} -> 4.7
R42: 3 | S42: {=INDEX('2026 tavasz'!$B$5:$Y$19,match(R42, '2026 tavasz'!$Y$5:$Y$19, 0),1)} -> Molnár György | T42: {=INDEX('2026 tavasz'!$B$5:$Y$19,match(R42, '2026 tavasz'!$Y$5:$Y$19, 0),23)} -> 4.5
R43: 4 | S43: {=INDEX('2026 tavasz'!$B$5:$Y$19,match(R43, '2026 tavasz'!$Y$5:$Y$19, 0),1)} -> Jávor Tamás | T43: {=INDEX('2026 tavasz'!$B$5:$Y$19,match(R43, '2026 tavasz'!$Y$5:$Y$19, 0),23)} -> 4.3
R44: 5 | S44: {=INDEX('2026 tavasz'!$B$5:$Y$19,match(R44, '2026 tavasz'!$Y$5:$Y$19, 0),1)} -> Varga Szabolcs | T44: {=INDEX('2026 tavasz'!$B$5:$Y$19,match(R44, '2026 tavasz'!$Y$5:$Y$19, 0),23)} -> 4
R45: 6 | S45: {=INDEX('2026 tavasz'!$B$5:$Y$19,match(R45, '2026 tavasz'!$Y$5:$Y$19, 0),1)} -> Szikora István | T45: {=INDEX('2026 tavasz'!$B$5:$Y$19,match(R45, '2026 tavasz'!$Y$5:$Y$19, 0),23)} -> 2.7
R46: 7 | S46: {=INDEX('2026 tavasz'!$B$5:$Y$19,match(R46, '2026 tavasz'!$Y$5:$Y$19, 0),1)} -> Barcsik Kristóf | T46: {=INDEX('2026 tavasz'!$B$5:$Y$19,match(R46, '2026 tavasz'!$Y$5:$Y$19, 0),23)} -> 2.6
...

Sheet Tippjáték
C2: Kezdő súly | D2: kitűzött cél | E2: ='2026 tavasz'!V3 -> Leadandó | G2: =B4 -> Barcsik Kristóf | H2: =B5 -> Galgóczy Ádám | I2: =B6 -> Jávor Tamás | J2: =B7 -> Krekuska Gábor | K2: =B8 -> Molnár György | L2: =B9 -> Varga Szabolcs | M2: =B10 -> Vaspál Gergő | N2: =B11 -> Várnoki Ádám | O2: =B12 -> Szikora István | P2: =B13 -> Kováts Tibor | Q2: =B14 -> Zorván Zoárd | R2: =B15 -> Beötthy Tímea | S2: =B16 -> Kellős György | T2: Jákob Tamás | U2: Tóth Roland
B3: ='2026 Tavasz diagram'!B4
B4: ='2026 Tavasz diagram'!B5 -> Barcsik Kristóf | C4: ='2026 tavasz'!C5 -> 116.1 | D4: ='2026 tavasz'!U5 -> 112 | E4: ='2026 tavasz'!V5 -> 4.1 | G4: Igen | H4: Nem | I4: Nem | J4: Nem | K4: Nem | L4: Nem | M4: Nem | N4: Nem | O4: Nem | P4: Igen | Q4: Nem | R4: Igen | S4: Nem | T4: Igen | U4: Nem
B5: ='2026 Tavasz diagram'!B6 -> Galgóczy Ádám | C5: ='2026 tavasz'!C6 -> 101.5 | D5: ='2026 tavasz'!U6 -> 98 | E5: ='2026 tavasz'!V6 -> 3.5 | G5: Igen | H5: Igen | I5: Igen | J5: Igen | K5: Igen | L5: Igen | M5: Igen | N5: Igen | O5: Igen | P5: Igen | Q5: Igen | R5: Igen | S5: Igen | T5: Igen | U5: Nem
B6: ='2026 Tavasz diagram'!B7 -> Jávor Tamás | C6: ='2026 tavasz'!C7 -> 116.3 | D6: ='2026 tavasz'!U7 -> 113 | E6: ='2026 tavasz'!V7 -> 3.3 | G6: Igen | H6: Nem | I6: Igen | J6: Igen | K6: Igen | L6: Igen | M6: Igen | N6: Nem | O6: Igen | P6: Igen | Q6: Igen | R6: Nem | S6: Igen | T6: Igen | U6: Igen
B7: ='2026 Tavasz diagram'!B8 -> Krekuska Gábor | C7: ='2026 tavasz'!C8 -> 87.7 | D7: ='2026 tavasz'!U8 -> 85 | E7: ='2026 tavasz'!V8 -> 2.7 | G7: Igen | H7: Igen | I7: Igen | J7: Igen | K7: Igen | L7: Igen | M7: Igen | N7: Igen | O7: Igen | P7: Igen | Q7: Igen | R7: Igen | S7: Igen | T7: Igen | U7: Nem
B8: ='2026 Tavasz diagram'!B9 -> Molnár György | C8: ='2026 tavasz'!C9 -> 88.3 | D8: ='2026 tavasz'!U9 -> 80 | E8: ='2026 tavasz'!V9 -> 8.3 | G8: Igen | H8: Igen | I8: Nem | J8: Igen | K8: Igen | L8: Nem | M8: Igen | N8: Nem | O8: Igen | P8: Nem | Q8: Nem | R8: Igen | S8: Igen | T8: Nem | U8: Nem
B9: ='2026 Tavasz diagram'!B10 -> Varga Szabolcs | C9: ='2026 tavasz'!C10 -> 105.3 | D9: ='2026 tavasz'!U10 -> 95 | E9: ='2026 tavasz'!V10 -> 10.3 | G9: Nem | H9: Nem | I9: Igen | J9: Nem | K9: Nem | L9: Igen | M9: Nem | N9: Nem | O9: Igen | P9: Nem | Q9: Nem | R9: Igen | S9: Nem | T9: Nem | U9: Nem
B10: ='2026 Tavasz diagram'!B11 -> Vaspál Gergő | C10: ='2026 tavasz'!C11 -> 92.3 | D10: ='2026 tavasz'!U11 -> 89 | E10: ='2026 tavasz'!V11 -> 3.3 | G10: Igen | H10: Nem | I10: Nem | J10: Nem | K10: Igen | L10: Nem | M10: Igen | N10: Igen | O10: Igen | P10: Igen | Q10: Nem | R10: Igen | S10: Igen | T10: Nem | U10: Nem
B11: ='2026 Tavasz diagram'!B12 -> Várnoki Ádám | C11: ='2026 tavasz'!C12 -> 108.4 | D11: ='2026 tavasz'!U12 -> 100 | E11: ='2026 tavasz'!V12 -> 8.4 | G11: Igen | H11: Nem | I11: Nem | J11: Igen | K11: Nem | L11: Igen | M11: Nem | N11: Igen | O11: Igen | P11: Igen | Q11: Nem | R11: Igen | S11: Nem | T11: Nem | U11: Nem
B12: ='2026 Tavasz diagram'!B13 -> Szikora István | C12: ='2026 tavasz'!C13 -> 102.1 | D12: ='2026 tavasz'!U13 -> 95 | E12: ='2026 tavasz'!V13 -> 7.1 | G12: Nem | H12: Nem | I12: Nem | J12: Nem | K12: Nem | L12: Nem | M12: Nem | N12: Nem | O12: Igen | P12: Nem | Q12: Nem | R12: Igen | S12: Nem | T12: Nem | U12: Igen
B13: ='2026 Tavasz diagram'!B14 -> Kováts Tibor | C13: ='2026 tavasz'!C14 -> 97.2 | D13: ='2026 tavasz'!U14 -> 95.9 | E13: ='2026 tavasz'!V14 -> 1.3 | G13: Igen | H13: Nem | I13: Igen | J13: Igen | K13: Igen | L13: Igen | M13: Igen | N13: Igen | O13: Igen | P13: Igen | Q13: Igen | R13: Igen | S13: Nem | T13: Nem | U13: Nem
B14: ='2026 Tavasz diagram'!B15 -> Zorván Zoárd | C14: ='2026 tavasz'!C15 -> 80.1 | D14: ='2026 tavasz'!U15 -> 72 | E14: ='2026 tavasz'!V15 -> 8.1 | G14: Igen | H14: Nem | I14: Nem | J14: Nem | K14: Nem | L14: Nem | M14: Nem | N14: Nem | O14: Igen | P14: Nem | Q14: Igen | R14: Nem | S14: Nem | T14: Nem | U14: Igen
B15: ='2026 Tavasz diagram'!B16 -> Beötthy Tímea | C15: ='2026 tavasz'!C16 -> 63.1 | D15: ='2026 tavasz'!U16 -> 55 | E15: ='2026 tavasz'!V16 -> 8.1 | G15: Igen | H15: Nem | I15: Nem | J15: Nem | K15: Nem | L15: Nem | M15: Igen | N15: Nem | O15: Igen | P15: Nem | Q15: Nem | R15: Igen | S15: Igen | T15: Nem | U15: Nem
B16: ='2026 Tavasz diagram'!B17 -> Kellős György | C16: ='2026 tavasz'!C17 -> 68.6 | D16: ='2026 tavasz'!U17 -> 72 | E16: ='2026 tavasz'!V17 -> -3.4 | G16: Igen | H16: Nem | I16: Nem | J16: Nem | K16: Nem | L16: Nem | M16: Igen | N16: Nem | O16: Igen | P16: Igen | Q16: Nem | R16: Nem | S16: Igen | T16: Nem | U16: Nem
B17: ='2026 Tavasz diagram'!B18 -> Jákob Tamás | C17: ='2026 tavasz'!I18 -> 103 | D17: ='2026 tavasz'!U18 -> 97 | E17: ='2026 tavasz'!V18 -> 6 | G17: Igen | H17: Nem | I17: Igen | J17: Nem | K17: Igen | L17: Nem | M17: Nem | N17: Nem | O17: Nem | P17: Igen | Q17: Nem | R17: Nem | S17: Nem | T17: Igen | U17: Nem
B18: ='2026 Tavasz diagram'!B19 -> Tóth Roland | C18: ='2026 tavasz'!I19 -> 93.6 | D18: ='2026 tavasz'!U19 -> 83.6 | E18: ='2026 tavasz'!V19 -> 10 | G18: Igen | H18: Nem | I18: Nem | J18: Nem | K18: Nem | L18: Nem | M18: Nem | N18: Nem | O18: Nem | P18: Nem | Q18: Nem | R18: Nem | S18: Nem | T18: Nem | U18: Igen
B22: ='2026 Tavasz diagram'!B20
C23: kitűzött cél | D23: Jelenlegi | E23: Teljesül? | F23: Ennyit kéne... | G23: ...hetente leadni: | I23: Találat
B24: ='2026 Tavasz diagram'!B22 -> Barcsik Kristóf | C24: =D4 -> 112 | D24: =IF('2026 tavasz'!T5="",C4,'2026 tavasz'!T5) -> 113.5 | E24: =IF(D24<C24,"Igen","Nem") -> Nem | F24: =D24-C24 -> 1.5 | G24: =F24/10 -> 0.15 | I24: 0
B25: ='2026 Tavasz diagram'!B23 -> Galgóczy Ádám | C25: =D5 -> 98 | D25: =IF('2026 tavasz'!T6="",C5,'2026 tavasz'!T6) -> 102.4 | E25: =IF(D25<C25,"Igen","Nem") -> Nem | F25: =D25-C25 -> 4.4 | G25: =F25/10 -> 0.44 | I25: 0
B26: ='2026 Tavasz diagram'!B24 -> Jávor Tamás | C26: =D6 -> 113 | D26: =IF('2026 tavasz'!T7="",C6,'2026 tavasz'!T7) -> 112 | E26: =IF(D26<C26,"Igen","Nem") -> Igen | F26: =D26-C26 -> -1 | G26: =F26/10 -> -0.1 | I26: 0
B27: ='2026 Tavasz diagram'!B25 -> Krekuska Gábor | C27: =D7 -> 85 | D27: =IF('2026 tavasz'!T8="",C7,'2026 tavasz'!T8) -> 87.3 | E27: =IF(D27<C27,"Igen","Nem") -> Nem | F27: =D27-C27 -> 2.3 | G27: =F27/10 -> 0.23 | I27: 0
B28: ='2026 Tavasz diagram'!B26 -> Molnár György | C28: =D8 -> 80 | D28: =IF('2026 tavasz'!T9="",C8,'2026 tavasz'!T9) -> 83.8 | E28: =IF(D28<C28,"Igen","Nem") -> Nem | F28: =D28-C28 -> 3.8 | G28: =F28/10 -> 0.38 | I28: 0
B29: ='2026 Tavasz diagram'!B27 -> Varga Szabolcs | C29: =D9 -> 95 | D29: =IF('2026 tavasz'!T10="",C9,'2026 tavasz'!T10) -> 101.3 | E29: =IF(D29<C29,"Igen","Nem") -> Nem | F29: =D29-C29 -> 6.3 | G29: =F29/10 -> 0.63 | I29: 0
B30: ='2026 Tavasz diagram'!B28 -> Vaspál Gergő | C30: =D10 -> 89 | D30: =IF('2026 tavasz'!T11="",C10,'2026 tavasz'!T11) -> 92.5 | E30: =IF(D30<C30,"Igen","Nem") -> Nem | F30: =D30-C30 -> 3.5 | G30: =F30/10 -> 0.35 | I30: 0
B31: ='2026 Tavasz diagram'!B29 -> Várnoki Ádám | C31: =D11 -> 100 | D31: =IF('2026 tavasz'!T12="",C11,'2026 tavasz'!T12) -> 101.9 | E31: =IF(D31<C31,"Igen","Nem") -> Nem | F31: =D31-C31 -> 1.9 | G31: =F31/10 -> 0.19 | I31: 0
B32: ='2026 Tavasz diagram'!B30 -> Szikora István | C32: =D12 -> 95 | D32: =IF('2026 tavasz'!T13="",C12,'2026 tavasz'!T13) -> 99.4 | E32: =IF(D32<C32,"Igen","Nem") -> Nem | F32: =D32-C32 -> 4.4 | G32: =F32/10 -> 0.44 | I32: 0
B33: ='2026 Tavasz diagram'!B31 -> Kováts Tibor | C33: =D13 -> 95.9 | D33: =IF('2026 tavasz'!T14="",C13,'2026 tavasz'!T14) -> 97.2 | E33: =IF(D33<C33,"Igen","Nem") -> Nem | F33: =D33-C33 -> 1.3 | G33: =F33/10 -> 0.13 | I33: 0
B34: ='2026 Tavasz diagram'!B32 -> Zorván Zoárd | C34: =D14 -> 72 | D34: =IF('2026 tavasz'!T15="",C14,'2026 tavasz'!T15) -> 75.4 | E34: =IF(D34<C34,"Igen","Nem") -> Nem | F34: =D34-C34 -> 3.4 | G34: =F34/10 -> 0.34 | I34: 0
B35: ='2026 Tavasz diagram'!B33 -> Beötthy Tímea | C35: =D15 -> 55 | D35: =IF('2026 tavasz'!T16="",C15,'2026 tavasz'!T16) -> 63 | E35: =IF(D35<C35,"Igen","Nem") -> Nem | F35: =D35-C35 -> 8 | G35: =F35/10 -> 0.8 | I35: 0
B36: ='2026 Tavasz diagram'!B34 -> Kellős György | C36: =D16 -> 72 | D36: ='2026 tavasz'!T17 -> 69.6 | E36: =IF(D36>C36,"Igen","Nem") -> Nem | F36: =D36-C36 -> -2.4 | G36: =F36/10 -> -0.24 | I36: 0
B37: ='2026 Tavasz diagram'!B35 -> Jákob Tamás | C37: =D17 -> 97 | D37: =IF('2026 tavasz'!T18="",C17,'2026 tavasz'!T18) -> 102.2 | E37: =IF(D37<C37,"Igen","Nem") -> Nem | F37: =D37-C37 -> 5.2 | G37: =F37/10 -> 0.52 | I37: 0
B38: ='2026 Tavasz diagram'!B36 -> Tóth Roland | C38: =D18 -> 83.6 | D38: =IF('2026 tavasz'!T19="",C18,'2026 tavasz'!T19) -> 92.4 | E38: =IF(D38<C38,"Igen","Nem") -> Nem | F38: =D38-C38 -> 8.8 | G38: =F38/10 -> 0.88 | I38: 0
C41: Progresszió - teljesült a kitűzött cél...
C42: negyede | D42: fele | E42: háromnegyede | F42: Teljesült
C43: Nekikezdett! | D43: Jól halad! | E43: Majdnem kész! | F43: Kész a test.
B44: ='2026 Tavasz diagram'!B22 -> Barcsik Kristóf | C44: =IF(D24<(C24+E4*0.75),"Igen","Nem") -> Igen | D44: =IF(D24<(C24+E4*0.5),"Igen","Nem") -> Igen | E44: =IF(D24<(C24+E4*0.25),"Igen","Nem") -> Nem | F44: =IF(D24<(C24),"Igen","Nem") -> Nem | H44: ='2026 Tavasz diagram'!B22 -> Barcsik Kristóf | I44: =IF(D24="",0,IF(D24>C4,0,(C4-D24)/E4)) -> 0.63414634
B45: ='2026 Tavasz diagram'!B23 -> Galgóczy Ádám | C45: =IF(D25<(C25+E5*0.75),"Igen","Nem") -> Nem | D45: =IF(D25<(C25+E5*0.5),"Igen","Nem") -> Nem | E45: =IF(D25<(C25+E5*0.25),"Igen","Nem") -> Nem | F45: =IF(D25<(C25+E5*0.25),"Igen","Nem") -> Nem | H45: ='2026 Tavasz diagram'!B23 -> Galgóczy Ádám | I45: =IF(D25="",0,IF(D25>C5,0,(C5-D25)/E5)) -> 0
B46: ='2026 Tavasz diagram'!B24 -> Jávor Tamás | C46: =IF(D26<(C26+E6*0.75),"Igen","Nem") -> Igen | D46: =IF(D26<(C26+E6*0.5),"Igen","Nem") -> Igen | E46: =IF(D26<(C26+E6*0.25),"Igen","Nem") -> Igen | F46: =IF(D26<(C26),"Igen","Nem") -> Igen | H46: ='2026 Tavasz diagram'!B24 -> Jávor Tamás | I46: =IF(D26="",0,IF(D26>C6,0,(C6-D26)/E6)) -> 1.3030303
...

Sheet Éves adatsor
C3: 45698 | D3: 45705 | E3: 45712 | F3: 45719 | G3: 45726 | H3: 45733 | I3: 45740 | J3: 45747 | K3: 45754 | L3: 45761 | M3: 45769 | N3: 45775 | O3: 45782 | P3: 45789 | Q3: 45796 | R3: 45803 | S3: 45810 | T3: 45818 | U3: 45824 | V3: 45831 | W3: 45838 | X3: 45845 | Y3: 45852 | Z3: 45859 | AA3: 45866 | AE3: 45894 | AF3: 45901 | AG3: 45908 | AH3: 45915 | AI3: 45922 | AJ3: 45929 | AK3: 45936 | AL3: 45943 | AM3: 45950 | AN3: 45957 | AO3: 45964 | AP3: 45971 | AQ3: 45978 | AR3: 45985 | AS3: 45992 | AT3: 45999
C4: 7. hét | D4: 8. hét | E4: 9. hét | F4: 10. hét | G4: 11. hét | H4: 12. hét | I4: 13. hét | J4: 14. hét | K4: 15. hét | L4: 16. hét | M4: 17. hét | N4: 18. hét | O4: 19. hét | P4: 20. hét | Q4: 21. hét | R4: 22. hét | S4: 23. hét | T4: 24. hét | U4: 25 .hét | V4: 26. hét | W4: 27. hét | X4: 28. hét | Y4: 29. hét | Z4: 30. hét | AA4: 31. hét | AB4: 32. hét | AC4: 33.hét | AD4: 34. hét | AE4: 35. hét | AF4: 36. hét | AG4: 37 .hét | AH4: 38. hét | AI4: 39. hét | AJ4: 40. hét | AK4: 41. hét | AL4: 42. hét | AM4: 43. hét | AN4: 44. hét | AO4: 45. hét | AP4: 46. hét | AQ4: 47. hét | AR4: 48. hét | AS4: 49. hét | AT4: 50. hét
B5: Barcsik Kristóf | C5: 113.7 | D5: 113 | E5: 113.3 | F5: 113.8 | G5: 113.3 | H5: 114 | I5: 113.6 | J5: 115.2 | K5: 114.3 | L5: 114.6 | M5: 114 | N5: 114.7 | O5: 114.8 | P5: 115.6 | Q5: 116.6 | R5: 115.1 | S5: 115.2 | T5: 114.8 | U5: 115.8 | V5: 116.7 | W5: 114.9 | X5: 116.6 | Y5: 116.6 | Z5: 115.2 | AA5: 114.8 | AE5: ='2026 tavasz'!C5 -> 116.1 | AF5: ='2026 tavasz'!D5 -> 116.1 | AG5: ='2026 tavasz'!E5 -> 116.1 | AH5: ='2026 tavasz'!F5 -> 113.4 | AI5: ='2026 tavasz'!G5 -> 113.6 | AJ5: ='2026 tavasz'!H5 -> 113 | AK5: ='2026 tavasz'!I5 -> 113.5 | AL5: ='2026 tavasz'!J5 -> 113.5 | ... AT5: ='2026 tavasz'!R5
B6: Galgóczy Ádám | C6: 107.5 | D6: 106.2 | E6: 105.3 | F6: 106 | G6: 106 | H6: 106.3 | I6: 103.6 | J6: 102.5 | K6: 102.4 | L6: 102.6 | M6: 103.3 | N6: 103.3 | O6: 103.3 | P6: 102.2 | Q6: 103 | R6: 103.9 | S6: 99.4 | T6: 100.5 | U6: 102 | V6: 101.1 | W6: 101.3 | X6: 102.6 | Y6: 101.5 | Z6: 102.3 | AA6: 102.6 | AE6: ='2026 tavasz'!C6 -> 101.5 | AF6: ='2026 tavasz'!D6 -> 101.7 | AG6: ='2026 tavasz'!E6 -> 100.9 | AH6: ='2026 tavasz'!F6 -> 101.1 | AI6: ='2026 tavasz'!G6 -> 101 | AJ6: ='2026 tavasz'!H6 -> 102 | AK6: ='2026 tavasz'!I6 -> 101.6 | AL6: ='2026 tavasz'!J6 -> 102.4 | ... AT6: ='2026 tavasz'!R6
B7: Jávor Tamás | C7: 117.7 | D7: 117.7 | E7: 117.6 | F7: 118 | G7: 118.1 | H7: 117 | I7: 116.1 | J7: 116.4 | K7: 115.5 | L7: 115.5 | M7: 115.6 | N7: 115.3 | O7: 114.5 | P7: 114.1 | Q7: 114.6 | R7: 114.6 | S7: 113.6 | T7: 112.5 | U7: 112.5 | V7: 112.2 | W7: 112.2 | X7: 111.3 | Y7: 111.3 | Z7: 110.6 | AA7: 110.6 | AE7: ='2026 tavasz'!C7 -> 116.3 | AF7: ='2026 tavasz'!D7 -> 116 | AG7: ='2026 tavasz'!E7 -> 114 | AH7: ='2026 tavasz'!F7 -> 114.3 | AI7: ='2026 tavasz'!G7 -> 112.6 | AJ7: ='2026 tavasz'!H7 -> 113.6 | AK7: ='2026 tavasz'!I7 -> 112.4 | AL7: ='2026 tavasz'!J7 -> 112 | ... AT7: ='2026 tavasz'!R7
B8: Krekuska Gábor | C8: 89 | D8: 88.4 | E8: 88.1 | F8: 87 | G8: 87.7 | H8: 87.5 | I8: 87.4 | J8: 88.5 | K8: 87.2 | L8: 87.8 | M8: 88.2 | N8: 89.7 | O8: 89.9 | P8: 88 | Q8: 87.6 | R8: 88.1 | S8: 85.6 | T8: 88 | U8: 86.8 | V8: 87.8 | W8: 88.1 | X8: 88.2 | Y8: 88.2 | Z8: 88.5 | AA8: 87.8 | AE8: ='2026 tavasz'!C8 -> 87.7 | AF8: ='2026 tavasz'!D8 -> 88 | AG8: ='2026 tavasz'!E8 -> 88 | AH8: ='2026 tavasz'!F8 -> 87.7 | AI8: ='2026 tavasz'!G8 -> 87.7 | AJ8: ='2026 tavasz'!H8 -> 87.2 | AK8: ='2026 tavasz'!I8 -> 88 | AL8: ='2026 tavasz'!J8 -> 87.3 | ... AT8: ='2026 tavasz'!R8
B9: Molnár György | C9: 94.3 | D9: 92.5 | E9: 92.5 | F9: 91.7 | G9: 92.3 | H9: 92.1 | I9: 93 | J9: 93 | K9: 93 | L9: 92.8 | M9: 93.4 | N9: 93.2 | O9: 93.9 | P9: 91.7 | Q9: 93 | R9: 93.7 | S9: 90.6 | T9: 91.7 | U9: 92.4 | V9: 92.5 | W9: 91.4 | X9: 91.2 | Y9: 91.6 | Z9: 90.6 | AA9: 89.8 | AE9: ='2026 tavasz'!C9 -> 88.3 | AF9: ='2026 tavasz'!D9 -> 87.2 | AG9: ='2026 tavasz'!E9 -> 86.1 | AH9: ='2026 tavasz'!F9 -> 85.6 | AI9: ='2026 tavasz'!G9 -> 84.7 | AJ9: ='2026 tavasz'!H9 -> 83.8 | AK9: ='2026 tavasz'!I9 -> 85 | AL9: ='2026 tavasz'!J9 -> 83.8 | ... AT9: ='2026 tavasz'!R9
B10: Varga Szabolcs | C10: 98.7 | D10: 98.3 | E10: 98.1 | F10: 98 | G10: 98.1 | H10: 97.9 | I10: 97.7 | J10: 97.2 | K10: 97.9 | L10: 98 | M10: 98.7 | N10: 98 | O10: 98.1 | P10: 97.8 | Q10: 97.7 | R10: 96.6 | S10: 96.2 | T10: 98.4 | U10: 99 | V10: 98.2 | W10: 99 | X10: 97.9 | Y10: 99.3 | Z10: 100 | AA10: 100.8 | AE10: ='2026 tavasz'!C10 -> 105.3 | AF10: ='2026 tavasz'!D10 -> 104 | AG10: ='2026 tavasz'!E10 -> 104 | AH10: ='2026 tavasz'!F10 -> 102.6 | AI10: ='2026 tavasz'!G10 -> 101.9 | AJ10: ='2026 tavasz'!H10 -> 102.3 | AK10: ='2026 tavasz'!I10 -> 102.3 | AL10: ='2026 tavasz'!J10 -> 101.3 | ... AT10: ='2026 tavasz'!R10
B11: Vaspál Gergő | C11: 89.3 | D11: 91.2 | E11: 92.1 | F11: 92.3 | G11: 91.5 | H11: 91.6 | I11: 93.4 | J11: 93.1 | K11: 92.1 | L11: 93.4 | M11: 93 | N11: 93.8 | O11: 92.9 | P11: 92.9 | Q11: 93.7 | R11: 91.9 | S11: 92.8 | T11: 91 | U11: 88.9 | V11: 89.9 | W11: 89.1 | X11: 89.2 | Y11: 89.2 | Z11: 89 | AA11: 90.2 | AE11: ='2026 tavasz'!C11 -> 92.3 | AF11: ='2026 tavasz'!D11 -> 92.2 | AG11: ='2026 tavasz'!E11 -> 91.8 | AH11: ='2026 tavasz'!F11 -> 92.9 | AI11: ='2026 tavasz'!G11 -> 93.3 | AJ11: ='2026 tavasz'!H11 -> 91.9 | AK11: ='2026 tavasz'!I11 -> 92.5 | AL11: ='2026 tavasz'!J11 -> 92.5 | ... AT11: ='2026 tavasz'!R11
B12: Várnoki Ádám | C12: 106 | D12: 105.9 | E12: 105.7 | F12: 104.8 | G12: 103.2 | H12: 103.2 | I12: 103.3 | J12: 102.9 | K12: 102 | L12: 102.6 | M12: 103.2 | N12: 102.8 | O12: 102.3 | P12: 103 | Q12: 103.1 | R12: 103.3 | S12: 102 | T12: 103.3 | U12: 103.8 | V12: 103.5 | W12: 103.5 | X12: 103.5 | Y12: 103.6 | Z12: 103.8 | AA12: 103.6 | AE12: ='2026 tavasz'!C12 -> 108.4 | AF12: ='2026 tavasz'!D12 -> 107 | AG12: ='2026 tavasz'!E12 -> 107.4 | AH12: ='2026 tavasz'!F12 -> 106.5 | AI12: ='2026 tavasz'!G12 -> 104 | AJ12: ='2026 tavasz'!H12 -> 102.9 | AK12: ='2026 tavasz'!I12 -> 103 | AL12: ='2026 tavasz'!J12 -> 101.9 | ... AT12: ='2026 tavasz'!R12
B13: Szikora István | C13: 100 | D13: 100 | E13: 100 | F13: 100 | G13: 100 | H13: 100 | I13: 100 | J13: 100 | K13: 100 | L13: 100 | M13: 100 | N13: 100 | O13: 100 | P13: 100 | Q13: 100 | R13: 100 | S13: 100 | T13: 100 | U13: 100.5 | V13: 98.7 | W13: 98.8 | X13: 99.5 | Y13: 102 | Z13: 102 | AA13: 100.8 | AE13: ='2026 tavasz'!C13 -> 102.1 | AF13: ='2026 tavasz'!D13 -> 102.2 | AG13: ='2026 tavasz'!E13 -> 102.8 | AH13: ='2026 tavasz'!F13 -> 101.7 | AI13: ='2026 tavasz'!G13 -> 101 | AJ13: ='2026 tavasz'!H13 -> 100.3 | AK13: ='2026 tavasz'!I13 -> 99.9 | AL13: ='2026 tavasz'!J13 -> 99.4 | ... AT13: ='2026 tavasz'!R13

Sheet Éves diagram
C4: ='Éves adatsor'!C4 -> 7. hét | D4: ='Éves adatsor'!D4 -> 8. hét | E4: ='Éves adatsor'!E4 -> 9. hét | F4: ='Éves adatsor'!F4 -> 10. hét | G4: ='Éves adatsor'!G4 -> 11. hét | H4: ='Éves adatsor'!H4 -> 12. hét | I4: ='Éves adatsor'!I4 -> 13. hét | J4: ='Éves adatsor'!J4 -> 14. hét | ... Z4: ='Éves adatsor'!Z4 -> 30. hét | AA4: 31. hét | AB4: 32. hét | AC4: 33.hét | AD4: 34. hét | AE4: 35. hét | AF4: 36. hét | AG4: 37 .hét | AH4: 38. hét | AI4: 39. hét | AJ4: 40. hét | AK4: 41. hét | AL4: 42. hét | AM4: 43. hét | AN4: 44. hét | AO4: 45. hét | AP4: 46. hét | AQ4: 47. hét | AR4: 48. hét | AS4: 49. hét | AT4: 50. hét | AU4: Változás (Kg)
B5: ='Éves adatsor'!B5 -> Barcsik Kristóf | C5: ű | D5: =LEFT('Éves adatsor'!D5, LEN('Éves adatsor'!D5) - 3) -> 113,0 | E5: =LEFT('Éves adatsor'!E5, LEN('Éves adatsor'!E5) - 3) -> 113,3 | F5: =LEFT('Éves adatsor'!F5, LEN('Éves adatsor'!F5) - 3) -> 113,8 | G5: =LEFT('Éves adatsor'!G5, LEN('Éves adatsor'!G5) - 3) -> 113,3 | H5: =LEFT('Éves adatsor'!H5, LEN('Éves adatsor'!H5) - 3) -> 114,0 | I5: =LEFT('Éves adatsor'!I5, LEN('Éves adatsor'!I5) - 3) -> 113,6 | J5: =LEFT('Éves adatsor'!J5, LEN('Éves adatsor'!J5) - 3) -> 115,2 | K5: =LEFT('Éves adatsor'!K5, LEN('Éves adatsor'!K5) - 3) -> 114,3 | ... AA5: =LEFT('Éves adatsor'!AA5, LEN('Éves adatsor'!AA5) - 3) -> 114,8 | AE5: =LEFT('Éves adatsor'!AE5, LEN('Éves adatsor'!AE5) - 3) -> 116,1 | AF5: =LEFT('Éves adatsor'!AF5, LEN('Éves adatsor'!AF5) - 3) -> 116,1 | AG5: =LEFT('Éves adatsor'!AG5, LEN('Éves adatsor'!AG5) - 3) -> 116,1 | AH5: =LEFT('Éves adatsor'!AH5, LEN('Éves adatsor'!AH5) - 3) -> 113,4 | AI5: =LEFT('Éves adatsor'!AI5, LEN('Éves adatsor'!AI5) - 3) -> 113,6 | AJ5: =LEFT('Éves adatsor'!AJ5, LEN('Éves adatsor'!AJ5) - 3) -> 113,0 | AK5: =LEFT('Éves adatsor'!AK5, LEN('Éves adatsor'!AK5) - 3) -> 113,5 | AL5: =LEFT('Éves adatsor'!AL5, LEN('Éves adatsor'!AL5) - 3) -> 113,5 | ... AT5: =LEFT('Éves adatsor'!AT5, LEN('Éves adatsor'!AT5) - 3) -> #VALUE! | AU5: =AT5-C5 -> #VALUE!
B6: ='Éves adatsor'!B6 -> Galgóczy Ádám | C6: =LEFT('Éves adatsor'!C6, LEN('Éves adatsor'!C6) - 3) -> 107,5 | D6: =LEFT('Éves adatsor'!D6, LEN('Éves adatsor'!D6) - 3) -> 106,2 | E6: =LEFT('Éves adatsor'!E6, LEN('Éves adatsor'!E6) - 3) -> 105,3 | F6: =LEFT('Éves adatsor'!F6, LEN('Éves adatsor'!F6) - 3) -> 106,0 | G6: =LEFT('Éves adatsor'!G6, LEN('Éves adatsor'!G6) - 3) -> 106,0 | H6: =LEFT('Éves adatsor'!H6, LEN('Éves adatsor'!H6) - 3) -> 106,3 | I6: =LEFT('Éves adatsor'!I6, LEN('Éves adatsor'!I6) - 3) -> 103,6 | J6: =LEFT('Éves adatsor'!J6, LEN('Éves adatsor'!J6) - 3) -> 102,5 | ... AA6: =LEFT('Éves adatsor'!AA6, LEN('Éves adatsor'!AA6) - 3) -> 102,6 | AE6: =LEFT('Éves adatsor'!AE6, LEN('Éves adatsor'!AE6) - 3) -> 101,5 | AF6: =LEFT('Éves adatsor'!AF6, LEN('Éves adatsor'!AF6) - 3) -> 101,7 | AG6: =LEFT('Éves adatsor'!AG6, LEN('Éves adatsor'!AG6) - 3) -> 100,9 | AH6: =LEFT('Éves adatsor'!AH6, LEN('Éves adatsor'!AH6) - 3) -> 101,1 | AI6: =LEFT('Éves adatsor'!AI6, LEN('Éves adatsor'!AI6) - 3) -> 101,0 | AJ6: =LEFT('Éves adatsor'!AJ6, LEN('Éves adatsor'!AJ6) - 3) -> 102,0 | AK6: =LEFT('Éves adatsor'!AK6, LEN('Éves adatsor'!AK6) - 3) -> 101,6 | AL6: =LEFT('Éves adatsor'!AL6, LEN('Éves adatsor'!AL6) - 3) -> 102,4 | ... AT6: =LEFT('Éves adatsor'!AT6, LEN('Éves adatsor'!AT6) - 3) -> #VALUE! | AU6: =AT6-C6 -> #VALUE!
B7: ='Éves adatsor'!B7 -> Jávor Tamás | C7: =LEFT('Éves adatsor'!C7, LEN('Éves adatsor'!C7) - 3) -> 117,7 | D7: =LEFT('Éves adatsor'!D7, LEN('Éves adatsor'!D7) - 3) -> 117,7 | E7: =LEFT('Éves adatsor'!E7, LEN('Éves adatsor'!E7) - 3) -> 117,6 | F7: =LEFT('Éves adatsor'!F7, LEN('Éves adatsor'!F7) - 3) -> 118,0 | G7: =LEFT('Éves adatsor'!G7, LEN('Éves adatsor'!G7) - 3) -> 118,1 | H7: =LEFT('Éves adatsor'!H7, LEN('Éves adatsor'!H7) - 3) -> 117,0 | I7: =LEFT('Éves adatsor'!I7, LEN('Éves adatsor'!I7) - 3) -> 116,1 | J7: =LEFT('Éves adatsor'!J7, LEN('Éves adatsor'!J7) - 3) -> 116,4 | ... AA7: =LEFT('Éves adatsor'!AA7, LEN('Éves adatsor'!AA7) - 3) -> 110,6 | AE7: =LEFT('Éves adatsor'!AE7, LEN('Éves adatsor'!AE7) - 3) -> 116,3 | AF7: =LEFT('Éves adatsor'!AF7, LEN('Éves adatsor'!AF7) - 3) -> 116,0 | AG7: =LEFT('Éves adatsor'!AG7, LEN('Éves adatsor'!AG7) - 3) -> 114,0 | AH7: =LEFT('Éves adatsor'!AH7, LEN('Éves adatsor'!AH7) - 3) -> 114,3 | AI7: =LEFT('Éves adatsor'!AI7, LEN('Éves adatsor'!AI7) - 3) -> 112,6 | AJ7: =LEFT('Éves adatsor'!AJ7, LEN('Éves adatsor'!AJ7) - 3) -> 113,6 | AK7: =LEFT('Éves adatsor'!AK7, LEN('Éves adatsor'!AK7) - 3) -> 112,4 | AL7: =LEFT('Éves adatsor'!AL7, LEN('Éves adatsor'!AL7) - 3) -> 112,0 | ... AT7: =LEFT('Éves adatsor'!AT7, LEN('Éves adatsor'!AT7) - 3) -> #VALUE! | AU7: =AT7-C7 -> #VALUE!
B8: ='Éves adatsor'!B8 -> Krekuska Gábor | C8: =LEFT('Éves adatsor'!C8, LEN('Éves adatsor'!C8) - 3) -> 89,0 | D8: =LEFT('Éves adatsor'!D8, LEN('Éves adatsor'!D8) - 3) -> 88,4 | E8: =LEFT('Éves adatsor'!E8, LEN('Éves adatsor'!E8) - 3) -> 88,1 | F8: =LEFT('Éves adatsor'!F8, LEN('Éves adatsor'!F8) - 3) -> 87,0 | G8: =LEFT('Éves adatsor'!G8, LEN('Éves adatsor'!G8) - 3) -> 87,7 | H8: =LEFT('Éves adatsor'!H8, LEN('Éves adatsor'!H8) - 3) -> 87,5 | I8: =LEFT('Éves adatsor'!I8, LEN('Éves adatsor'!I8) - 3) -> 87,4 | J8: =LEFT('Éves adatsor'!J8, LEN('Éves adatsor'!J8) - 3) -> 88,5 | ... AA8: =LEFT('Éves adatsor'!AA8, LEN('Éves adatsor'!AA8) - 3) -> 87,8 | AE8: =LEFT('Éves adatsor'!AE8, LEN('Éves adatsor'!AE8) - 3) -> 87,7 | AF8: =LEFT('Éves adatsor'!AF8, LEN('Éves adatsor'!AF8) - 3) -> 88,0 | AG8: =LEFT('Éves adatsor'!AG8, LEN('Éves adatsor'!AG8) - 3) -> 88,0 | AH8: =LEFT('Éves adatsor'!AH8, LEN('Éves adatsor'!AH8) - 3) -> 87,7 | AI8: =LEFT('Éves adatsor'!AI8, LEN('Éves adatsor'!AI8) - 3) -> 87,7 | AJ8: =LEFT('Éves adatsor'!AJ8, LEN('Éves adatsor'!AJ8) - 3) -> 87,2 | AK8: =LEFT('Éves adatsor'!AK8, LEN('Éves adatsor'!AK8) - 3) -> 88,0 | AL8: =LEFT('Éves adatsor'!AL8, LEN('Éves adatsor'!AL8) - 3) -> 87,3 | ... AT8: =LEFT('Éves adatsor'!AT8, LEN('Éves adatsor'!AT8) - 3) -> #VALUE! | AU8: =AT8-C8 -> #VALUE!
B9: ='Éves adatsor'!B9 -> Molnár György | C9: =LEFT('Éves adatsor'!C9, LEN('Éves adatsor'!C9) - 3) -> 94,3 | D9: =LEFT('Éves adatsor'!D9, LEN('Éves adatsor'!D9) - 3) -> 92,5 | E9: =LEFT('Éves adatsor'!E9, LEN('Éves adatsor'!E9) - 3) -> 92,5 | F9: =LEFT('Éves adatsor'!F9, LEN('Éves adatsor'!F9) - 3) -> 91,7 | G9: =LEFT('Éves adatsor'!G9, LEN('Éves adatsor'!G9) - 3) -> 92,3 | H9: =LEFT('Éves adatsor'!H9, LEN('Éves adatsor'!H9) - 3) -> 92,1 | I9: =LEFT('Éves adatsor'!I9, LEN('Éves adatsor'!I9) - 3) -> 93,0 | J9: =LEFT('Éves adatsor'!J9, LEN('Éves adatsor'!J9) - 3) -> 93,0 | ... AA9: =LEFT('Éves adatsor'!AA9, LEN('Éves adatsor'!AA9) - 3) -> 89,8 | AE9: =LEFT('Éves adatsor'!AE9, LEN('Éves adatsor'!AE9) - 3) -> 88,3 | AF9: =LEFT('Éves adatsor'!AF9, LEN('Éves adatsor'!AF9) - 3) -> 87,2 | AG9: =LEFT('Éves adatsor'!AG9, LEN('Éves adatsor'!AG9) - 3) -> 86,1 | AH9: =LEFT('Éves adatsor'!AH9, LEN('Éves adatsor'!AH9) - 3) -> 85,6 | AI9: =LEFT('Éves adatsor'!AI9, LEN('Éves adatsor'!AI9) - 3) -> 84,7 | AJ9: =LEFT('Éves adatsor'!AJ9, LEN('Éves adatsor'!AJ9) - 3) -> 83,8 | AK9: =LEFT('Éves adatsor'!AK9, LEN('Éves adatsor'!AK9) - 3) -> 85,0 | AL9: =LEFT('Éves adatsor'!AL9, LEN('Éves adatsor'!AL9) - 3) -> 83,8 | ... AT9: =LEFT('Éves adatsor'!AT9, LEN('Éves adatsor'!AT9) - 3) -> #VALUE! | AU9: =AT9-C9 -> #VALUE!
B10: ='Éves adatsor'!B10 -> Varga Szabolcs | C10: =LEFT('Éves adatsor'!C10, LEN('Éves adatsor'!C10) - 3) -> 98,7 | D10: =LEFT('Éves adatsor'!D10, LEN('Éves adatsor'!D10) - 3) -> 98,3 | E10: =LEFT('Éves adatsor'!E10, LEN('Éves adatsor'!E10) - 3) -> 98,1 | F10: =LEFT('Éves adatsor'!F10, LEN('Éves adatsor'!F10) - 3) -> 98,0 | G10: =LEFT('Éves adatsor'!G10, LEN('Éves adatsor'!G10) - 3) -> 98,1 | H10: =LEFT('Éves adatsor'!H10, LEN('Éves adatsor'!H10) - 3) -> 97,9 | I10: =LEFT('Éves adatsor'!I10, LEN('Éves adatsor'!I10) - 3) -> 97,7 | J10: =LEFT('Éves adatsor'!J10, LEN('Éves adatsor'!J10) - 3) -> 97,2 | ... AA10: =LEFT('Éves adatsor'!AA10, LEN('Éves adatsor'!AA10) - 3) -> 100,8 | AE10: =LEFT('Éves adatsor'!AE10, LEN('Éves adatsor'!AE10) - 3) -> 105,3 | AF10: =LEFT('Éves adatsor'!AF10, LEN('Éves adatsor'!AF10) - 3) -> 104,0 | AG10: =LEFT('Éves adatsor'!AG10, LEN('Éves adatsor'!AG10) - 3) -> 104,0 | AH10: =LEFT('Éves adatsor'!AH10, LEN('Éves adatsor'!AH10) - 3) -> 102,6 | AI10: =LEFT('Éves adatsor'!AI10, LEN('Éves adatsor'!AI10) - 3) -> 101,9 | AJ10: =LEFT('Éves adatsor'!AJ10, LEN('Éves adatsor'!AJ10) - 3) -> 102,3 | AK10: =LEFT('Éves adatsor'!AK10, LEN('Éves adatsor'!AK10) - 3) -> 102,3 | AL10: =LEFT('Éves adatsor'!AL10, LEN('Éves adatsor'!AL10) - 3) -> 101,3 | ... AT10: =LEFT('Éves adatsor'!AT10, LEN('Éves adatsor'!AT10) - 3) -> #VALUE! | AU10: =AT10-C10 -> #VALUE!
B11: ='Éves adatsor'!B11 -> Vaspál Gergő | C11: =LEFT('Éves adatsor'!C11, LEN('Éves adatsor'!C11) - 3) -> 89,3 | D11: =LEFT('Éves adatsor'!D11, LEN('Éves adatsor'!D11) - 3) -> 91,2 | E11: =LEFT('Éves adatsor'!E11, LEN('Éves adatsor'!E11) - 3) -> 92,1 | F11: =LEFT('Éves adatsor'!F11, LEN('Éves adatsor'!F11) - 3) -> 92,3 | G11: =LEFT('Éves adatsor'!G11, LEN('Éves adatsor'!G11) - 3) -> 91,5 | H11: =LEFT('Éves adatsor'!H11, LEN('Éves adatsor'!H11) - 3) -> 91,6 | I11: =LEFT('Éves adatsor'!I11, LEN('Éves adatsor'!I11) - 3) -> 93,4 | J11: =LEFT('Éves adatsor'!J11, LEN('Éves adatsor'!J11) - 3) -> 93,1 | ... AA11: =LEFT('Éves adatsor'!AA11, LEN('Éves adatsor'!AA11) - 3) -> 90,2 | AE11: =LEFT('Éves adatsor'!AE11, LEN('Éves adatsor'!AE11) - 3) -> 92,3 | AF11: =LEFT('Éves adatsor'!AF11, LEN('Éves adatsor'!AF11) - 3) -> 92,2 | AG11: =LEFT('Éves adatsor'!AG11, LEN('Éves adatsor'!AG11) - 3) -> 91,8 | AH11: =LEFT('Éves adatsor'!AH11, LEN('Éves adatsor'!AH11) - 3) -> 92,9 | AI11: =LEFT('Éves adatsor'!AI11, LEN('Éves adatsor'!AI11) - 3) -> 93,3 | AJ11: =LEFT('Éves adatsor'!AJ11, LEN('Éves adatsor'!AJ11) - 3) -> 91,9 | AK11: =LEFT('Éves adatsor'!AK11, LEN('Éves adatsor'!AK11) - 3) -> 92,5 | AL11: =LEFT('Éves adatsor'!AL11, LEN('Éves adatsor'!AL11) - 3) -> 92,5 | ... AT11: =LEFT('Éves adatsor'!AT11, LEN('Éves adatsor'!AT11) - 3) -> #VALUE! | AU11: =AT11-C11 -> #VALUE!
B12: ='Éves adatsor'!B12 -> Várnoki Ádám | C12: =LEFT('Éves adatsor'!C12, LEN('Éves adatsor'!C12) - 3) -> 106,0 | D12: =LEFT('Éves adatsor'!D12, LEN('Éves adatsor'!D12) - 3) -> 105,9 | E12: =LEFT('Éves adatsor'!E12, LEN('Éves adatsor'!E12) - 3) -> 105,7 | F12: =LEFT('Éves adatsor'!F12, LEN('Éves adatsor'!F12) - 3) -> 104,8 | G12: =LEFT('Éves adatsor'!G12, LEN('Éves adatsor'!G12) - 3) -> 103,2 | H12: =LEFT('Éves adatsor'!H12, LEN('Éves adatsor'!H12) - 3) -> 103,2 | I12: =LEFT('Éves adatsor'!I12, LEN('Éves adatsor'!I12) - 3) -> 103,3 | J12: =LEFT('Éves adatsor'!J12, LEN('Éves adatsor'!J12) - 3) -> 102,9 | ... AA12: =LEFT('Éves adatsor'!AA12, LEN('Éves adatsor'!AA12) - 3) -> 103,6 | AE12: =LEFT('Éves adatsor'!AE12, LEN('Éves adatsor'!AE12) - 3) -> 108,4 | AF12: =LEFT('Éves adatsor'!AF12, LEN('Éves adatsor'!AF12) - 3) -> 107,0 | AG12: =LEFT('Éves adatsor'!AG12, LEN('Éves adatsor'!AG12) - 3) -> 107,4 | AH12: =LEFT('Éves adatsor'!AH12, LEN('Éves adatsor'!AH12) - 3) -> 106,5 | AI12: =LEFT('Éves adatsor'!AI12, LEN('Éves adatsor'!AI12) - 3) -> 104,0 | AJ12: =LEFT('Éves adatsor'!AJ12, LEN('Éves adatsor'!AJ12) - 3) -> 102,9 | AK12: =LEFT('Éves adatsor'!AK12, LEN('Éves adatsor'!AK12) - 3) -> 103,0 | AL12: =LEFT('Éves adatsor'!AL12, LEN('Éves adatsor'!AL12) - 3) -> 101,9 | ... AT12: =LEFT('Éves adatsor'!AT12, LEN('Éves adatsor'!AT12) - 3) -> #VALUE! | AU12: =AT12-C12 -> #VALUE!
B13: ='Éves adatsor'!B13 -> Szikora István | C13: =LEFT('Éves adatsor'!C13, LEN('Éves adatsor'!C13) - 3) -> 100,0 | D13: =LEFT('Éves adatsor'!D13, LEN('Éves adatsor'!D13) - 3) -> 100,0 | E13: =LEFT('Éves adatsor'!E13, LEN('Éves adatsor'!E13) - 3) -> 100,0 | F13: =LEFT('Éves adatsor'!F13, LEN('Éves adatsor'!F13) - 3) -> 100,0 | G13: =LEFT('Éves adatsor'!G13, LEN('Éves adatsor'!G13) - 3) -> 100,0 | H13: =LEFT('Éves adatsor'!H13, LEN('Éves adatsor'!H13) - 3) -> 100,0 | I13: =LEFT('Éves adatsor'!I13, LEN('Éves adatsor'!I13) - 3) -> 100,0 | J13: =LEFT('Éves adatsor'!J13, LEN('Éves adatsor'!J13) - 3) -> 100,0 | ... AA13: =LEFT('Éves adatsor'!AA13, LEN('Éves adatsor'!AA13) - 3) -> 100,8 | AE13: =LEFT('Éves adatsor'!AE13, LEN('Éves adatsor'!AE13) - 3) -> 102,1 | AF13: =LEFT('Éves adatsor'!AF13, LEN('Éves adatsor'!AF13) - 3) -> 102,2 | AG13: =LEFT('Éves adatsor'!AG13, LEN('Éves adatsor'!AG13) - 3) -> 102,8 | AH13: =LEFT('Éves adatsor'!AH13, LEN('Éves adatsor'!AH13) - 3) -> 101,7 | AI13: =LEFT('Éves adatsor'!AI13, LEN('Éves adatsor'!AI13) - 3) -> 101,0 | AJ13: =LEFT('Éves adatsor'!AJ13, LEN('Éves adatsor'!AJ13) - 3) -> 100,3 | AK13: =LEFT('Éves adatsor'!AK13, LEN('Éves adatsor'!AK13) - 3) -> 99,9 | AL13: =LEFT('Éves adatsor'!AL13, LEN('Éves adatsor'!AL13) - 3) -> 99,4 | ... AT13: =LEFT('Éves adatsor'!AT13, LEN('Éves adatsor'!AT13) - 3) -> #VALUE! | AU13: =AT13-C13 -> #VALUE!
B14: ='Éves adatsor'!B14
C17: =C4 -> 7. hét | D17: =D4 -> 8. hét | E17: =E4 -> 9. hét | F17: =F4 -> 10. hét | G17: =G4 -> 11. hét | H17: =H4 -> 12. hét | I17: =I4 -> 13. hét | J17: =J4 -> 14. hét | ... Z17: =Z4 -> 30. hét | AA17: 31. hét | AB17: 32. hét | AC17: 33.hét | AD17: 34. hét | AE17: 35. hét | AF17: 36. hét | AG17: 37 .hét | AH17: 38. hét | AI17: 39. hét | AJ17: 40. hét | AK17: 41. hét | AL17: 42. hét | AM17: 43. hét | AN17: 44. hét | AO17: 45. hét | AP17: 46. hét | AQ17: 47. hét | AR17: 48. hét | AS17: 49. hét | AT17: 50. hét
B18: Barcsik Kristóf | C18: 0 | D18: =(D5-$C5)/$C5 -> #VALUE! | E18: =(E5-$C5)/$C5 -> #VALUE! | F18: =(F5-$C5)/$C5 -> #VALUE! | G18: =(G5-$C5)/$C5 -> #VALUE! | H18: =(H5-$C5)/$C5 -> #VALUE! | I18: =(I5-$C5)/$C5 -> #VALUE! | J18: =(J5-$C5)/$C5 -> #VALUE! | K18: =(K5-$C5)/$C5 -> #VALUE! | ... AA18: =(AA5-$C5)/$C5 -> #VALUE! | AE18: =(AE5-$C5)/$C5 -> #VALUE! | AF18: =(AF5-$C5)/$C5 -> #VALUE! | AG18: =(AG5-$C5)/$C5 -> #VALUE! | AH18: =(AH5-$C5)/$C5 -> #VALUE! | AI18: =(AI5-$C5)/$C5 -> #VALUE! | AJ18: =(AJ5-$C5)/$C5 -> #VALUE! | AK18: =(AK5-$C5)/$C5 -> #VALUE! | AL18: =(AL5-$C5)/$C5 -> #VALUE! | ... AT18: =(AT5-$C5)/$C5 -> #VALUE!
B19: Galgóczy Ádám | C19: 0 | D19: =(D6-$C6)/$C6 -> -0.012093023 | E19: =(E6-$C6)/$C6 -> -0.020465116 | F19: =(F6-$C6)/$C6 -> -0.013953488 | G19: =(G6-$C6)/$C6 -> -0.013953488 | H19: =(H6-$C6)/$C6 -> -0.011162791 | I19: =(I6-$C6)/$C6 -> -0.03627907 | J19: =(J6-$C6)/$C6 -> -0.046511628 | K19: =(K6-$C6)/$C6 -> -0.04744186 | ... AA19: =(AA6-$C6)/$C6 -> -0.045581395 | AE19: =(AE6-$C6)/$C6 -> -0.055813953 | AF19: =(AF6-$C6)/$C6 -> -0.053953488 | AG19: =(AG6-$C6)/$C6 -> -0.061395349 | AH19: =(AH6-$C6)/$C6 -> -0.059534884 | AI19: =(AI6-$C6)/$C6 -> -0.060465116 | AJ19: =(AJ6-$C6)/$C6 -> -0.051162791 | AK19: =(AK6-$C6)/$C6 -> -0.054883721 | AL19: =(AL6-$C6)/$C6 -> -0.04744186 | ... AT19: =(AT6-$C6)/$C6 -> #VALUE!
B20: Jávor Tamás | C20: 0 | D20: =(D7-$C7)/$C7 -> 0 | E20: =(E7-$C7)/$C7 -> -0.00084961767 | F20: =(F7-$C7)/$C7 -> 0.002548853 | G20: =(G7-$C7)/$C7 -> 0.0033984707 | H20: =(H7-$C7)/$C7 -> -0.0059473237 | I20: =(I7-$C7)/$C7 -> -0.013593883 | J20: =(J7-$C7)/$C7 -> -0.01104503 | K20: =(K7-$C7)/$C7 -> -0.018691589 | ... AA20: =(AA7-$C7)/$C7 -> -0.060322855 | AE20: =(AE7-$C7)/$C7 -> -0.011894647 | AF20: =(AF7-$C7)/$C7 -> -0.0144435 | AG20: =(AG7-$C7)/$C7 -> -0.031435854 | AH20: =(AH7-$C7)/$C7 -> -0.028887001 | AI20: =(AI7-$C7)/$C7 -> -0.043330501 | AJ20: =(AJ7-$C7)/$C7 -> -0.034834325 | AK20: =(AK7-$C7)/$C7 -> -0.045029737 | AL20: =(AL7-$C7)/$C7 -> -0.048428207 | ... AT20: =(AT7-$C7)/$C7 -> #VALUE!
B21: Krekuska Gábor | C21: 0 | D21: =(D8-$C8)/$C8 -> -0.006741573 | E21: =(E8-$C8)/$C8 -> -0.01011236 | F21: =(F8-$C8)/$C8 -> -0.02247191 | G21: =(G8-$C8)/$C8 -> -0.014606742 | H21: =(H8-$C8)/$C8 -> -0.016853933 | I21: =(I8-$C8)/$C8 -> -0.017977528 | J21: =(J8-$C8)/$C8 -> -0.0056179775 | K21: =(K8-$C8)/$C8 -> -0.020224719 | ... AA21: =(AA8-$C8)/$C8 -> -0.013483146 | AE21: =(AE8-$C8)/$C8 -> -0.014606742 | AF21: =(AF8-$C8)/$C8 -> -0.011235955 | AG21: =(AG8-$C8)/$C8 -> -0.011235955 | AH21: =(AH8-$C8)/$C8 -> -0.014606742 | AI21: =(AI8-$C8)/$C8 -> -0.014606742 | AJ21: =(AJ8-$C8)/$C8 -> -0.020224719 | AK21: =(AK8-$C8)/$C8 -> -0.011235955 | AL21: =(AL8-$C8)/$C8 -> -0.019101124 | ... AT21: =(AT8-$C8)/$C8 -> #VALUE!
B22: Molnár György | C22: 0 | D22: =(D9-$C9)/$C9 -> -0.019088017 | E22: =(E9-$C9)/$C9 -> -0.019088017 | F22: =(F9-$C9)/$C9 -> -0.02757158 | G22: =(G9-$C9)/$C9 -> -0.021208908 | H22: =(H9-$C9)/$C9 -> -0.023329799 | I22: =(I9-$C9)/$C9 -> -0.01378579 | J22: =(J9-$C9)/$C9 -> -0.01378579 | K22: =(K9-$C9)/$C9 -> -0.01378579 | ... AA22: =(AA9-$C9)/$C9 -> -0.047720042 | AE22: =(AE9-$C9)/$C9 -> -0.063626723 | AF22: =(AF9-$C9)/$C9 -> -0.075291622 | AG22: =(AG9-$C9)/$C9 -> -0.086956522 | AH22: =(AH9-$C9)/$C9 -> -0.092258749 | AI22: =(AI9-$C9)/$C9 -> -0.10180276 | AJ22: =(AJ9-$C9)/$C9 -> -0.11134677 | AK22: =(AK9-$C9)/$C9 -> -0.098621421 | AL22: =(AL9-$C9)/$C9 -> -0.11134677 | ... AT22: =(AT9-$C9)/$C9 -> #VALUE!
B23: Varga Szabolcs | C23: 0 | D23: =(D10-$C10)/$C10 -> -0.0040526849 | E23: =(E10-$C10)/$C10 -> -0.0060790274 | F23: =(F10-$C10)/$C10 -> -0.0070921986 | G23: =(G10-$C10)/$C10 -> -0.0060790274 | H23: =(H10-$C10)/$C10 -> -0.0081053698 | I23: =(I10-$C10)/$C10 -> -0.010131712 | J23: =(J10-$C10)/$C10 -> -0.015197568 | K23: =(K10-$C10)/$C10 -> -0.0081053698 | ... AA23: =(AA10-$C10)/$C10 -> 0.021276596 | AE23: =(AE10-$C10)/$C10 -> 0.066869301 | AF23: =(AF10-$C10)/$C10 -> 0.053698075 | AG23: =(AG10-$C10)/$C10 -> 0.053698075 | AH23: =(AH10-$C10)/$C10 -> 0.039513678 | AI23: =(AI10-$C10)/$C10 -> 0.032421479 | AJ23: =(AJ10-$C10)/$C10 -> 0.036474164 | AK23: =(AK10-$C10)/$C10 -> 0.036474164 | AL23: =(AL10-$C10)/$C10 -> 0.026342452 | ... AT23: =(AT10-$C10)/$C10 -> #VALUE!
B24: Vaspál Gergő | C24: 0 | D24: =(D11-$C11)/$C11 -> 0.021276596 | E24: =(E11-$C11)/$C11 -> 0.031354983 | F24: =(F11-$C11)/$C11 -> 0.033594625 | G24: =(G11-$C11)/$C11 -> 0.024636058 | H24: =(H11-$C11)/$C11 -> 0.025755879 | I24: =(I11-$C11)/$C11 -> 0.045912654 | J24: =(J11-$C11)/$C11 -> 0.042553191 | K24: =(K11-$C11)/$C11 -> 0.031354983 | ... AA24: =(AA11-$C11)/$C11 -> 0.010078387 | AE24: =(AE11-$C11)/$C11 -> 0.033594625 | AF24: =(AF11-$C11)/$C11 -> 0.032474804 | AG24: =(AG11-$C11)/$C11 -> 0.027995521 | AH24: =(AH11-$C11)/$C11 -> 0.04031355 | AI24: =(AI11-$C11)/$C11 -> 0.044792833 | AJ24: =(AJ11-$C11)/$C11 -> 0.029115342 | AK24: =(AK11-$C11)/$C11 -> 0.035834267 | AL24: =(AL11-$C11)/$C11 -> 0.035834267 | ... AT24: =(AT11-$C11)/$C11 -> #VALUE!
B25: Várnoki Ádám | C25: 0 | D25: =(D12-$C12)/$C12 -> -0.00094339623 | E25: =(E12-$C12)/$C12 -> -0.0028301887 | F25: =(F12-$C12)/$C12 -> -0.011320755 | G25: =(G12-$C12)/$C12 -> -0.026415094 | H25: =(H12-$C12)/$C12 -> -0.026415094 | I25: =(I12-$C12)/$C12 -> -0.025471698 | J25: =(J12-$C12)/$C12 -> -0.029245283 | K25: =(K12-$C12)/$C12 -> -0.037735849 | ... AA25: =(AA12-$C12)/$C12 -> -0.022641509 | AE25: =(AE12-$C12)/$C12 -> 0.022641509 | AF25: =(AF12-$C12)/$C12 -> 0.0094339623 | AG25: =(AG12-$C12)/$C12 -> 0.013207547 | AH25: =(AH12-$C12)/$C12 -> 0.0047169811 | AI25: =(AI12-$C12)/$C12 -> -0.018867925 | AJ25: =(AJ12-$C12)/$C12 -> -0.029245283 | AK25: =(AK12-$C12)/$C12 -> -0.028301887 | AL25: =(AL12-$C12)/$C12 -> -0.038679245 | ... AT25: =(AT12-$C12)/$C12 -> #VALUE!
B26: Szikora Isván | C26: 0 | D26: =(D13-$C13)/$C13 -> 0 | E26: =(E13-$C13)/$C13 -> 0 | F26: =(F13-$C13)/$C13 -> 0 | G26: =(G13-$C13)/$C13 -> 0 | H26: =(H13-$C13)/$C13 -> 0 | I26: =(I13-$C13)/$C13 -> 0 | J26: =(J13-$C13)/$C13 -> 0 | K26: =(K13-$C13)/$C13 -> 0 | ... AA26: =(AA13-$C13)/$C13 -> 0.008 | AE26: =(AE13-$C13)/$C13 -> 0.021 | AF26: =(AF13-$C13)/$C13 -> 0.022 | AG26: =(AG13-$C13)/$C13 -> 0.028 | AH26: =(AH13-$C13)/$C13 -> 0.017 | AI26: =(AI13-$C13)/$C13 -> 0.01 | AJ26: =(AJ13-$C13)/$C13 -> 0.003 | AK26: =(AK13-$C13)/$C13 -> -0.001 | AL26: =(AL13-$C13)/$C13 -> -0.006 | ... AT26: =(AT13-$C13)/$C13 -> #VALUE!
C65: Helyezés | D65: Versenyző | E65: Kezdő érték | F65: Végeredmény | G65: százalék | H65: súlykülönbség
C66: 1. | D66: =$B$7 -> Jávor Tamás | E66: =$C$7 -> 117,7 | F66: =$AA$7 -> 110,6 | G66: =$AA$20 -> -0.060322855 | H66: =$AA$7-$C$7 -> -7.1
C67: 2. | D67: =$B$22 -> Molnár György | E67: =$C$9 -> 94,3 | F67: =$AA$9 -> 89,8 | G67: =$AA$22 -> -0.047720042 | H67: =$AA$9-$C$9 -> -4.5
C68: 3. | D68: =$B$6 -> Galgóczy Ádám | E68: =$C$6 -> 107,5 | F68: =$AA$6 -> 102,6 | G68: =$AA$19 -> -0.045581395 | H68: =$AA$6-$C$6 -> -4.9
C69: 4. | D69: =$B$12 -> Várnoki Ádám | E69: =$C$12 -> 106,0 | F69: =$AA$12 -> 103,6 | G69: =$AA$25 -> -0.022641509 | H69: =$AA$12-$C$12 -> -2.4
C70: 5. | D70: =$B$21 -> Krekuska Gábor | E70: =$C$8 -> 89,0 | F70: =$AA$8 -> 87,8 | G70: =$AA$21 -> -0.013483146 | H70: =$AA$8-$C$8 -> -1.2
C71: 6. | D71: =$B$13 -> Szikora István | E71: =$C$13 -> 100,0 | F71: =$AA$13 -> 100,8 | G71: =$AA$26 -> 0.008 | H71: =$AA$13-$C$13 -> 0.8
C72: 7. | D72: =$B$5 -> Barcsik Kristóf | E72: =$C$5 -> ű | F72: =$AA$5 -> 114,8 | G72: =$AA$18 -> #VALUE! | H72: =$AA$5-$C$5 -> #VALUE!
C73: 8. | D73: =$B$11 -> Vaspál Gergő | E73: =$C$11 -> 89,3 | F73: =$AA$11 -> 90,2 | G73: =$AA$24 -> 0.010078387 | H73: =$AA$11-$C$11 -> 0.9
C74: 9. | D74: =$B$10 -> Varga Szabolcs | E74: =$C$10 -> 98,7 | F74: =$AA$10 -> 100,8 | G74: =$AA$23 -> 0.021276596 | H74: =$AA$10-$C$10 -> 2.1
D76: össz változás: | H76: =SUM(H66:H74) -> #VALUE!
D77: átlagos fogyás: | G77: =SUM(G66:G74)/9 -> #VALUE! | H77: =H76/9 -> #VALUE!
B81: éves helyezés | D81: kezdős súly | E81: Záró súly | G81: Változás (%) | H81: Változás (Kg)
A82: 9 | B82: 1. | C82: =B9 -> Molnár György | D82: =C9 -> 94,3 | E82: =AT9 -> #VALUE! | G82: =AT22 -> #VALUE! | H82: =AU9 -> #VALUE!
A83: 6 | B83: 2. | C83: =B6 -> Galgóczy Ádám | D83: =C6 -> 107,5 | E83: =AT6 -> #VALUE! | G83: =AT19 -> #VALUE! | H83: =AU6 -> #VALUE!
A84: 8 | B84: 3. | C84: =B8 -> Krekuska Gábor | D84: =C8 -> 89,0 | E84: =AT8 -> #VALUE! | G84: =AT21 -> #VALUE! | H84: =AU8 -> #VALUE!
A85: 7 | B85: 4. | C85: =B7 -> Jávor Tamás | D85: =C7 -> 117,7 | E85: =AT7 -> #VALUE! | G85: =AT20 -> #VALUE! | H85: =AU7 -> #VALUE!
A86: 13 | B86: 5. | C86: =B13 -> Szikora István | D86: =C13 -> 100,0 | E86: =AT13 -> #VALUE! | G86: =AT26 -> #VALUE! | H86: =AU13 -> #VALUE!
A87: 12 | B87: 6. | C87: =B12 -> Várnoki Ádám | D87: =C12 -> 106,0 | E87: =AT12 -> #VALUE! | G87: =AT25 -> #VALUE! | H87: =AU12 -> #VALUE!
...
